import User from '../models/userModel.js';
import AppError from '../utils/appError.js';
import catchAsync from '../utils/catchAsync.js';
export const getAllUsers = catchAsync(async (req, res) => {
  const users = await User.find();
  res.status(200).json({
    status: 'success',
    results: users.length,
    data: {
      users,
    },
  });
});

export const getUserById = catchAsync(async (req, res, next) => {
  const user = await User.findById(req.params.id);
  if (!user) {
    return next(new AppError('User not found', 404));
  }
  res.status(200).json({
    status: 'success',
    data: {
      user,
    },
  });
});
export const deleteUser = catchAsync(async (req, res, next) => {
  const user = await User.findByIdAndDelete(req.params.id);
  if (!user) {
    return next(new AppError('User not found', 404));
  }
  res.status(204).json({
    status: 'success',
    data: null,
  });
});
export const updateUser = catchAsync(async (req, res, next) => {
  const user = await User.findByIdAndUpdate(req.params.id, req.body, {
    new: true,
    runValidators: true,
  });
  if (!user) {
    return next(new AppError('User not found', 404));
  }
  res.status(200).json({
    status: 'success',
    data: {
      user,
    },
  });
});
